Workbook

Sheet README
A1: Efforts Engineers - Compressor Parts Photo Master Sheet
A2: Website photo catalogue by compressor brand, series, model and part. Brands: Grasso, Sabroe, Kirloskar, Vilter, Mycom, Carrier.
A4: SHEETS
A5: Summary | B5: Live progress count by brand. Updates itself when you change Photo Status.
A6: Master_Photo_Sheet | B6: One row per photo slot (series x part). This is the working sheet. Fill the amber-header columns.
A7: Series | B7: 29 series with URL slugs and the models each series covers.
A8: Model_List | B8: Every model by brand and series, with a confidence tag showing how reliable each name is.
A9: Part_Categories | B9: 17 part categories with codes, URL slugs and a photo-shooting tip for each.
A10: Lists | B10: Brand codes and the dropdown values. Edit here to change the dropdowns.
A12: HOW TO USE
A13: 1 | B13: Shoot each part yourself (white background, 1200 x 1200 px, front view plus one angled view). Save the file using the name in the File Name column.
A14: 2 | B14: In Master_Photo_Sheet fill the amber columns: Part Description, Part Number, Material / Size, Photo Status, Photo Source, Photo View, Stock Status, Remarks.
A15: 3 | B15: Set Photo Status as the photo moves: To Shoot, Shot, Edited, Uploaded. Use Not Applicable if the series has no such part.
A16: 4 | B16: If a series needs several photos of one part type (for example different liner sizes), copy the row and change the last two digits of the Photo ID to -02, -03.
A17: 5 | B17: File Name, Photo ID, Compatible Models, Alt Text and Page URL fill themselves in. Do not type over them.
A19: COLOUR KEY
A20: Blue text on yellow | B20: Cells for you to fill in or edit.
A21: Black text on white | B21: Formulas or fixed reference data. Do not overwrite.
A23: DATA SOURCES AND CAVEATS
A24: Model names | B24: Taken from OEM product pages (GEA Grasso, Vilter / Copeland), OEM manual titles, Kirloskar's KC / KCX brochure, and supplier and used-equipment listings (IndiaMART, indianyellowpages, used-machinery dealers).
A25: Confidence tag | B25: Model_List marks each model as Confirmed (OEM page / manual title), Seen in supplier / used listings, or Verify with team. Please check every Verify row against your own catalogue before publishing.
A26: Not pulled | B26: Amocon, casparts.co.kr, Ralco Europa and Alfa OM were not used to build this list. Add anything they list that you also supply.
A27: Part numbers | B27: Left blank on purpose. Use Efforts Engineers' own part numbers or OEM manual numbers; do not copy another seller's numbers.
A28: Photos | B28: Competitor photos are copyrighted and often watermarked. Use your own photographs. Supplier photos only with written permission.
A29: Screw compressors | B29: Screw ranges (Sabroe SAB, Vilter VSS / VSM, Mycom screw, Grasso screw) are not included. Say if you want them added.
A30: Series model text | B30: Models Covered on the Series sheet is typed text. If you add a model on Model_List, also update that text.
A32: EXAMPLE OF A COMPLETED ROW (format only)
A33: Brand | B33: Series | C33: Part Category | D33: Part Description | E33: Part Number | F33: Material / Size | G33: Photo Status | H33: Photo Source | I33: Photo View | J33: Stock Status
A34: Kirloskar | B34: Kirloskar KC Series | C34: Cylinder Liner | D34: Liner for KC 4 (example only) | E34: EE-KC4-CLN-001 (example format) | F34: Cast iron; bore size per drawing | G34: Uploaded | H34: Own photo | I34: Angled | J34: In Stock

Sheet Summary
A1: Photo Progress Summary
A2: Counts update automatically from Master_Photo_Sheet. Percent uploaded excludes slots marked Not Applicable.
A4: Brand | B4: Series | C4: Models Listed | D4: Photo Slots | E4: To Shoot | F4: Shot | G4: Edited | H4: Uploaded | I4: Not Applicable | J4: % Uploaded
A5: Grasso | B5: =COUNTIFS(Series!$A$2:$A$30,A5) -> 5 | C5: =COUNTIFS(Model_List!$A$2:$A$171,A5) -> 35 | D5: =COUNTIFS(Master_Photo_Sheet!$B$2:$B$494,A5) -> 85 | E5: =COUNTIFS(Master_Photo_Sheet!$B$2:$B$494,$A5,Master_Photo_Sheet!$K$2:$K$494,"To Shoot") -> 85 | F5: =COUNTIFS(Master_Photo_Sheet!$B$2:$B$494,$A5,Master_Photo_Sheet!$K$2:$K$494,"Shot") -> 0 | G5: =COUNTIFS(Master_Photo_Sheet!$B$2:$B$494,$A5,Master_Photo_Sheet!$K$2:$K$494,"Edited") -> 0 | H5: =COUNTIFS(Master_Photo_Sheet!$B$2:$B$494,$A5,Master_Photo_Sheet!$K$2:$K$494,"Uploaded") -> 0 | I5: =COUNTIFS(Master_Photo_Sheet!$B$2:$B$494,$A5,Master_Photo_Sheet!$K$2:$K$494,"Not Applicable") -> 0 | J5: =IF(D5-I5=0,0,H5/(D5-I5)) -> 0
A6: Sabroe | B6: =COUNTIFS(Series!$A$2:$A$30,A6) -> 5 | C6: =COUNTIFS(Model_List!$A$2:$A$171,A6) -> 39 | D6: =COUNTIFS(Master_Photo_Sheet!$B$2:$B$494,A6) -> 85 | E6: =COUNTIFS(Master_Photo_Sheet!$B$2:$B$494,$A6,Master_Photo_Sheet!$K$2:$K$494,"To Shoot") -> 85 | F6: =COUNTIFS(Master_Photo_Sheet!$B$2:$B$494,$A6,Master_Photo_Sheet!$K$2:$K$494,"Shot") -> 0 | G6: =COUNTIFS(Master_Photo_Sheet!$B$2:$B$494,$A6,Master_Photo_Sheet!$K$2:$K$494,"Edited") -> 0 | H6: =COUNTIFS(Master_Photo_Sheet!$B$2:$B$494,$A6,Master_Photo_Sheet!$K$2:$K$494,"Uploaded") -> 0 | I6: =COUNTIFS(Master_Photo_Sheet!$B$2:$B$494,$A6,Master_Photo_Sheet!$K$2:$K$494,"Not Applicable") -> 0 | J6: =IF(D6-I6=0,0,H6/(D6-I6)) -> 0
A7: Kirloskar | B7: =COUNTIFS(Series!$A$2:$A$30,A7) -> 4 | C7: =COUNTIFS(Model_List!$A$2:$A$171,A7) -> 22 | D7: =COUNTIFS(Master_Photo_Sheet!$B$2:$B$494,A7) -> 68 | E7: =COUNTIFS(Master_Photo_Sheet!$B$2:$B$494,$A7,Master_Photo_Sheet!$K$2:$K$494,"To Shoot") -> 68 | F7: =COUNTIFS(Master_Photo_Sheet!$B$2:$B$494,$A7,Master_Photo_Sheet!$K$2:$K$494,"Shot") -> 0 | G7: =COUNTIFS(Master_Photo_Sheet!$B$2:$B$494,$A7,Master_Photo_Sheet!$K$2:$K$494,"Edited") -> 0 | H7: =COUNTIFS(Master_Photo_Sheet!$B$2:$B$494,$A7,Master_Photo_Sheet!$K$2:$K$494,"Uploaded") -> 0 | I7: =COUNTIFS(Master_Photo_Sheet!$B$2:$B$494,$A7,Master_Photo_Sheet!$K$2:$K$494,"Not Applicable") -> 0 | J7: =IF(D7-I7=0,0,H7/(D7-I7)) -> 0
A8: Vilter | B8: =COUNTIFS(Series!$A$2:$A$30,A8) -> 3 | C8: =COUNTIFS(Model_List!$A$2:$A$171,A8) -> 14 | D8: =COUNTIFS(Master_Photo_Sheet!$B$2:$B$494,A8) -> 51 | E8: =COUNTIFS(Master_Photo_Sheet!$B$2:$B$494,$A8,Master_Photo_Sheet!$K$2:$K$494,"To Shoot") -> 51 | F8: =COUNTIFS(Master_Photo_Sheet!$B$2:$B$494,$A8,Master_Photo_Sheet!$K$2:$K$494,"Shot") -> 0 | G8: =COUNTIFS(Master_Photo_Sheet!$B$2:$B$494,$A8,Master_Photo_Sheet!$K$2:$K$494,"Edited") -> 0 | H8: =COUNTIFS(Master_Photo_Sheet!$B$2:$B$494,$A8,Master_Photo_Sheet!$K$2:$K$494,"Uploaded") -> 0 | I8: =COUNTIFS(Master_Photo_Sheet!$B$2:$B$494,$A8,Master_Photo_Sheet!$K$2:$K$494,"Not Applicable") -> 0 | J8: =IF(D8-I8=0,0,H8/(D8-I8)) -> 0
A9: Mycom | B9: =COUNTIFS(Series!$A$2:$A$30,A9) -> 8 | C9: =COUNTIFS(Model_List!$A$2:$A$171,A9) -> 41 | D9: =COUNTIFS(Master_Photo_Sheet!$B$2:$B$494,A9) -> 136 | E9: =COUNTIFS(Master_Photo_Sheet!$B$2:$B$494,$A9,Master_Photo_Sheet!$K$2:$K$494,"To Shoot") -> 136 | F9: =COUNTIFS(Master_Photo_Sheet!$B$2:$B$494,$A9,Master_Photo_Sheet!$K$2:$K$494,"Shot") -> 0 | G9: =COUNTIFS(Master_Photo_Sheet!$B$2:$B$494,$A9,Master_Photo_Sheet!$K$2:$K$494,"Edited") -> 0 | H9: =COUNTIFS(Master_Photo_Sheet!$B$2:$B$494,$A9,Master_Photo_Sheet!$K$2:$K$494,"Uploaded") -> 0 | I9: =COUNTIFS(Master_Photo_Sheet!$B$2:$B$494,$A9,Master_Photo_Sheet!$K$2:$K$494,"Not Applicable") -> 0 | J9: =IF(D9-I9=0,0,H9/(D9-I9)) -> 0
A10: Carrier | B10: =COUNTIFS(Series!$A$2:$A$30,A10) -> 4 | C10: =COUNTIFS(Model_List!$A$2:$A$171,A10) -> 19 | D10: =COUNTIFS(Master_Photo_Sheet!$B$2:$B$494,A10) -> 68 | E10: =COUNTIFS(Master_Photo_Sheet!$B$2:$B$494,$A10,Master_Photo_Sheet!$K$2:$K$494,"To Shoot") -> 68 | F10: =COUNTIFS(Master_Photo_Sheet!$B$2:$B$494,$A10,Master_Photo_Sheet!$K$2:$K$494,"Shot") -> 0 | G10: =COUNTIFS(Master_Photo_Sheet!$B$2:$B$494,$A10,Master_Photo_Sheet!$K$2:$K$494,"Edited") -> 0 | H10: =COUNTIFS(Master_Photo_Sheet!$B$2:$B$494,$A10,Master_Photo_Sheet!$K$2:$K$494,"Uploaded") -> 0 | I10: =COUNTIFS(Master_Photo_Sheet!$B$2:$B$494,$A10,Master_Photo_Sheet!$K$2:$K$494,"Not Applicable") -> 0 | J10: =IF(D10-I10=0,0,H10/(D10-I10)) -> 0
A11: Total | B11: =SUM(B5:B10) -> 29 | C11: =SUM(C5:C10) -> 170 | D11: =SUM(D5:D10) -> 493 | E11: =SUM(E5:E10) -> 493 | F11: =SUM(F5:F10) -> 0 | G11: =SUM(G5:G10) -> 0 | H11: =SUM(H5:H10) -> 0 | I11: =SUM(I5:I10) -> 0 | J11: =IF(D11-I11=0,0,H11/(D11-I11)) -> 0
A13: Check: slots not matched to a status | D13: =D11-SUM(E11:I11) -> 0 | E13: Should be 0. A number here means a Photo Status cell is blank or mistyped.

Sheet Master_Photo_Sheet
A1: Sr No | B1: Brand | C1: Series | D1: Part Category | E1: Photo ID | F1: File Name | G1: Compatible Models | H1: Part Description | I1: Part Number | J1: Material / Size | K1: Photo Status | L1: Photo Source | M1: Photo View | N1: Stock Status | O1: Alt Text | P1: Page URL | Q1: Remarks
A2: =ROW()-1 -> 1 | B2: Grasso | C2: Grasso V Series | D2: Cylinder Liner | E2: =IFERROR(INDEX(Lists!$B$2:$B$7,MATCH(B2,Lists!$A$2:$A$7,0))&"-"&INDEX(Series!$C$2:$C$30,MATCH(C2,Series!$B$2:$B$30,0))&"-"&INDEX(Part_Categories!$A$2:$A$18,MATCH(D2,Part_Categories!$B$2:$B$18,0))&"-01","CHECK") -> GRA-V-CLN-01 | F2: =E2&".jpg" -> GRA-V-CLN-01.jpg | G2: =IFERROR(INDEX(Series!$F$2:$F$30,MATCH(C2,Series!$B$2:$B$30,0)),"") -> V 300, V 450, V 600, V 700, V 1100, V 1400 | K2: To Shoot | O2: =C2&" "&D2&" spare part - Efforts Engineers" -> Grasso V Series Cylinder Liner spare part - Efforts Engineers | P2: =IFERROR("/"&LOWER(B2)&"/"&INDEX(Series!$D$2:$D$30,MATCH(C2,Series!$B$2:$B$30,0))&"/"&INDEX(Part_Categories!$C$2:$C$18,MATCH(D2,Part_Categories!$B$2:$B$18,0)),"CHECK") -> /grasso/v-series/cylinder-liner
A3: =ROW()-1 -> 2 | B3: Grasso | C3: Grasso V Series | D3: Piston Assembly | E3: =IFERROR(INDEX(Lists!$B$2:$B$7,MATCH(B3,Lists!$A$2:$A$7,0))&"-"&INDEX(Series!$C$2:$C$30,MATCH(C3,Series!$B$2:$B$30,0))&"-"&INDEX(Part_Categories!$A$2:$A$18,MATCH(D3,Part_Categories!$B$2:$B$18,0))&"-01","CHECK") -> GRA-V-PST-01 | F3: =E3&".jpg" -> GRA-V-PST-01.jpg | G3: =IFERROR(INDEX(Series!$F$2:$F$30,MATCH(C3,Series!$B$2:$B$30,0)),"") -> V 300, V 450, V 600, V 700, V 1100, V 1400 | K3: To Shoot | O3: =C3&" "&D3&" spare part - Efforts Engineers" -> Grasso V Series Piston Assembly spare part - Efforts Engineers | P3: =IFERROR("/"&LOWER(B3)&"/"&INDEX(Series!$D$2:$D$30,MATCH(C3,Series!$B$2:$B$30,0))&"/"&INDEX(Part_Categories!$C$2:$C$18,MATCH(D3,Part_Categories!$B$2:$B$18,0)),"CHECK") -> /grasso/v-series/piston-assembly
A4: =ROW()-1 -> 3 | B4: Grasso | C4: Grasso V Series | D4: Piston Ring Set | E4: =IFERROR(INDEX(Lists!$B$2:$B$7,MATCH(B4,Lists!$A$2:$A$7,0))&"-"&INDEX(Series!$C$2:$C$30,MATCH(C4,Series!$B$2:$B$30,0))&"-"&INDEX(Part_Categories!$A$2:$A$18,MATCH(D4,Part_Categories!$B$2:$B$18,0))&"-01","CHECK") -> GRA-V-PRG-01 | F4: =E4&".jpg" -> GRA-V-PRG-01.jpg | G4: =IFERROR(INDEX(Series!$F$2:$F$30,MATCH(C4,Series!$B$2:$B$30,0)),"") -> V 300, V 450, V 600, V 700, V 1100, V 1400 | K4: To Shoot | O4: =C4&" "&D4&" spare part - Efforts Engineers" -> Grasso V Series Piston Ring Set spare part - Efforts Engineers | P4: =IFERROR("/"&LOWER(B4)&"/"&INDEX(Series!$D$2:$D$30,MATCH(C4,Series!$B$2:$B$30,0))&"/"&INDEX(Part_Categories!$C$2:$C$18,MATCH(D4,Part_Categories!$B$2:$B$18,0)),"CHECK") -> /grasso/v-series/piston-ring-set
A5: =ROW()-1 -> 4 | B5: Grasso | C5: Grasso V Series | D5: Connecting Rod | E5: =IFERROR(INDEX(Lists!$B$2:$B$7,MATCH(B5,Lists!$A$2:$A$7,0))&"-"&INDEX(Series!$C$2:$C$30,MATCH(C5,Series!$B$2:$B$30,0))&"-"&INDEX(Part_Categories!$A$2:$A$18,MATCH(D5,Part_Categories!$B$2:$B$18,0))&"-01","CHECK") -> GRA-V-CRD-01 | F5: =E5&".jpg" -> GRA-V-CRD-01.jpg | G5: =IFERROR(INDEX(Series!$F$2:$F$30,MATCH(C5,Series!$B$2:$B$30,0)),"") -> V 300, V 450, V 600, V 700, V 1100, V 1400 | K5: To Shoot | O5: =C5&" "&D5&" spare part - Efforts Engineers" -> Grasso V Series Connecting Rod spare part - Efforts Engineers | P5: =IFERROR("/"&LOWER(B5)&"/"&INDEX(Series!$D$2:$D$30,MATCH(C5,Series!$B$2:$B$30,0))&"/"&INDEX(Part_Categories!$C$2:$C$18,MATCH(D5,Part_Categories!$B$2:$B$18,0)),"CHECK") -> /grasso/v-series/connecting-rod
A6: =ROW()-1 -> 5 | B6: Grasso | C6: Grasso V Series | D6: Crankshaft | E6: =IFERROR(INDEX(Lists!$B$2:$B$7,MATCH(B6,Lists!$A$2:$A$7,0))&"-"&INDEX(Series!$C$2:$C$30,MATCH(C6,Series!$B$2:$B$30,0))&"-"&INDEX(Part_Categories!$A$2:$A$18,MATCH(D6,Part_Categories!$B$2:$B$18,0))&"-01","CHECK") -> GRA-V-CRK-01 | F6: =E6&".jpg" -> GRA-V-CRK-01.jpg | G6: =IFERROR(INDEX(Series!$F$2:$F$30,MATCH(C6,Series!$B$2:$B$30,0)),"") -> V 300, V 450, V 600, V 700, V 1100, V 1400 | K6: To Shoot | O6: =C6&" "&D6&" spare part - Efforts Engineers" -> Grasso V Series Crankshaft spare part - Efforts Engineers | P6: =IFERROR("/"&LOWER(B6)&"/"&INDEX(Series!$D$2:$D$30,MATCH(C6,Series!$B$2:$B$30,0))&"/"&INDEX(Part_Categories!$C$2:$C$18,MATCH(D6,Part_Categories!$B$2:$B$18,0)),"CHECK") -> /grasso/v-series/crankshaft
A7: =ROW()-1 -> 6 | B7: Grasso | C7: Grasso V Series | D7: Gudgeon Pin and Bush | E7: =IFERROR(INDEX(Lists!$B$2:$B$7,MATCH(B7,Lists!$A$2:$A$7,0))&"-"&INDEX(Series!$C$2:$C$30,MATCH(C7,Series!$B$2:$B$30,0))&"-"&INDEX(Part_Categories!$A$2:$A$18,MATCH(D7,Part_Categories!$B$2:$B$18,0))&"-01","CHECK") -> GRA-V-PIN-01 | F7: =E7&".jpg" -> GRA-V-PIN-01.jpg | G7: =IFERROR(INDEX(Series!$F$2:$F$30,MATCH(C7,Series!$B$2:$B$30,0)),"") -> V 300, V 450, V 600, V 700, V 1100, V 1400 | K7: To Shoot | O7: =C7&" "&D7&" spare part - Efforts Engineers" -> Grasso V Series Gudgeon Pin and Bush spare part - Efforts Engineers | P7: =IFERROR("/"&LOWER(B7)&"/"&INDEX(Series!$D$2:$D$30,MATCH(C7,Series!$B$2:$B$30,0))&"/"&INDEX(Part_Categories!$C$2:$C$18,MATCH(D7,Part_Categories!$B$2:$B$18,0)),"CHECK") -> /grasso/v-series/gudgeon-pin-and-bush
A8: =ROW()-1 -> 7 | B8: Grasso | C8: Grasso V Series | D8: Main Bearing and Bush | E8: =IFERROR(INDEX(Lists!$B$2:$B$7,MATCH(B8,Lists!$A$2:$A$7,0))&"-"&INDEX(Series!$C$2:$C$30,MATCH(C8,Series!$B$2:$B$30,0))&"-"&INDEX(Part_Categories!$A$2:$A$18,MATCH(D8,Part_Categories!$B$2:$B$18,0))&"-01","CHECK") -> GRA-V-BRG-01 | F8: =E8&".jpg" -> GRA-V-BRG-01.jpg | G8: =IFERROR(INDEX(Series!$F$2:$F$30,MATCH(C8,Series!$B$2:$B$30,0)),"") -> V 300, V 450, V 600, V 700, V 1100, V 1400 | K8: To Shoot | O8: =C8&" "&D8&" spare part - Efforts Engineers" -> Grasso V Series Main Bearing and Bush spare part - Efforts Engineers | P8: =IFERROR("/"&LOWER(B8)&"/"&INDEX(Series!$D$2:$D$30,MATCH(C8,Series!$B$2:$B$30,0))&"/"&INDEX(Part_Categories!$C$2:$C$18,MATCH(D8,Part_Categories!$B$2:$B$18,0)),"CHECK") -> /grasso/v-series/main-bearing-and-bush
A9: =ROW()-1 -> 8 | B9: Grasso | C9: Grasso V Series | D9: Suction Valve Plate | E9: =IFERROR(INDEX(Lists!$B$2:$B$7,MATCH(B9,Lists!$A$2:$A$7,0))&"-"&INDEX(Series!$C$2:$C$30,MATCH(C9,Series!$B$2:$B$30,0))&"-"&INDEX(Part_Categories!$A$2:$A$18,MATCH(D9,Part_Categories!$B$2:$B$18,0))&"-01","CHECK") -> GRA-V-SVP-01 | F9: =E9&".jpg" -> GRA-V-SVP-01.jpg | G9: =IFERROR(INDEX(Series!$F$2:$F$30,MATCH(C9,Series!$B$2:$B$30,0)),"") -> V 300, V 450, V 600, V 700, V 1100, V 1400 | K9: To Shoot | O9: =C9&" "&D9&" spare part - Efforts Engineers" -> Grasso V Series Suction Valve Plate spare part - Efforts Engineers | P9: =IFERROR("/"&LOWER(B9)&"/"&INDEX(Series!$D$2:$D$30,MATCH(C9,Series!$B$2:$B$30,0))&"/"&INDEX(Part_Categories!$C$2:$C$18,MATCH(D9,Part_Categories!$B$2:$B$18,0)),"CHECK") -> /grasso/v-series/suction-valve-plate
A10: =ROW()-1 -> 9 | B10: Grasso | C10: Grasso V Series | D10: Discharge Valve Assembly | E10: =IFERROR(INDEX(Lists!$B$2:$B$7,MATCH(B10,Lists!$A$2:$A$7,0))&"-"&INDEX(Series!$C$2:$C$30,MATCH(C10,Series!$B$2:$B$30,0))&"-"&INDEX(Part_Categories!$A$2:$A$18,MATCH(D10,Part_Categories!$B$2:$B$18,0))&"-01","CHECK") -> GRA-V-DVA-01 | F10: =E10&".jpg" -> GRA-V-DVA-01.jpg | G10: =IFERROR(INDEX(Series!$F$2:$F$30,MATCH(C10,Series!$B$2:$B$30,0)),"") -> V 300, V 450, V 600, V 700, V 1100, V 1400 | K10: To Shoot | O10: =C10&" "&D10&" spare part - Efforts Engineers" -> Grasso V Series Discharge Valve Assembly spare part - Efforts Engineers | P10: =IFERROR("/"&LOWER(B10)&"/"&INDEX(Series!$D$2:$D$30,MATCH(C10,Series!$B$2:$B$30,0))&"/"&INDEX(Part_Categories!$C$2:$C$18,MATCH(D10,Part_Categories!$B$2:$B$18,0)),"CHECK") -> /grasso/v-series/discharge-valve-assembly
A11: =ROW()-1 -> 10 | B11: Grasso | C11: Grasso V Series | D11: Valve Spring and Cage | E11: =IFERROR(INDEX(Lists!$B$2:$B$7,MATCH(B11,Lists!$A$2:$A$7,0))&"-"&INDEX(Series!$C$2:$C$30,MATCH(C11,Series!$B$2:$B$30,0))&"-"&INDEX(Part_Categories!$A$2:$A$18,MATCH(D11,Part_Categories!$B$2:$B$18,0))&"-01","CHECK") -> GRA-V-VSP-01 | F11: =E11&".jpg" -> GRA-V-VSP-01.jpg | G11: =IFERROR(INDEX(Series!$F$2:$F$30,MATCH(C11,Series!$B$2:$B$30,0)),"") -> V 300, V 450, V 600, V 700, V 1100, V 1400 | K11: To Shoot | O11: =C11&" "&D11&" spare part - Efforts Engineers" -> Grasso V Series Valve Spring and Cage spare part - Efforts Engineers | P11: =IFERROR("/"&LOWER(B11)&"/"&INDEX(Series!$D$2:$D$30,MATCH(C11,Series!$B$2:$B$30,0))&"/"&INDEX(Part_Categories!$C$2:$C$18,MATCH(D11,Part_Categories!$B$2:$B$18,0)),"CHECK") -> /grasso/v-series/valve-spring-and-cage
A12: =ROW()-1 -> 11 | B12: Grasso | C12: Grasso V Series | D12: Cylinder Head Cover | E12: =IFERROR(INDEX(Lists!$B$2:$B$7,MATCH(B12,Lists!$A$2:$A$7,0))&"-"&INDEX(Series!$C$2:$C$30,MATCH(C12,Series!$B$2:$B$30,0))&"-"&INDEX(Part_Categories!$A$2:$A$18,MATCH(D12,Part_Categories!$B$2:$B$18,0))&"-01","CHECK") -> GRA-V-HDC-01 | F12: =E12&".jpg" -> GRA-V-HDC-01.jpg | G12: =IFERROR(INDEX(Series!$F$2:$F$30,MATCH(C12,Series!$B$2:$B$30,0)),"") -> V 300, V 450, V 600, V 700, V 1100, V 1400 | K12: To Shoot | O12: =C12&" "&D12&" spare part - Efforts Engineers" -> Grasso V Series Cylinder Head Cover spare part - Efforts Engineers | P12: =IFERROR("/"&LOWER(B12)&"/"&INDEX(Series!$D$2:$D$30,MATCH(C12,Series!$B$2:$B$30,0))&"/"&INDEX(Part_Categories!$C$2:$C$18,MATCH(D12,Part_Categories!$B$2:$B$18,0)),"CHECK") -> /grasso/v-series/cylinder-head-cover
A13: =ROW()-1 -> 12 | B13: Grasso | C13: Grasso V Series | D13: Gasket and Overhaul Kit | E13: =IFERROR(INDEX(Lists!$B$2:$B$7,MATCH(B13,Lists!$A$2:$A$7,0))&"-"&INDEX(Series!$C$2:$C$30,MATCH(C13,Series!$B$2:$B$30,0))&"-"&INDEX(Part_Categories!$A$2:$A$18,MATCH(D13,Part_Categories!$B$2:$B$18,0))&"-01","CHECK") -> GRA-V-GSK-01 | F13: =E13&".jpg" -> GRA-V-GSK-01.jpg | G13: =IFERROR(INDEX(Series!$F$2:$F$30,MATCH(C13,Series!$B$2:$B$30,0)),"") -> V 300, V 450, V 600, V 700, V 1100, V 1400 | K13: To Shoot | O13: =C13&" "&D13&" spare part - Efforts Engineers" -> Grasso V Series Gasket and Overhaul Kit spare part - Efforts Engineers | P13: =IFERROR("/"&LOWER(B13)&"/"&INDEX(Series!$D$2:$D$30,MATCH(C13,Series!$B$2:$B$30,0))&"/"&INDEX(Part_Categories!$C$2:$C$18,MATCH(D13,Part_Categories!$B$2:$B$18,0)),"CHECK") -> /grasso/v-series/gasket-and-overhaul-kit
... A494: =ROW()-1 -> 493 | B494: Carrier | C494: Carrier 06E Series | D494: Safety Head and Relief Valve | E494: =IFERROR(INDEX(Lists!$B$2:$B$7,MATCH(B494,Lists!$A$2:$A$7,0))&"-"&INDEX(Series!$C$2:$C$30,MATCH(C494,Series!$B$2:$B$30,0))&"-"&INDEX(Part_Categories!$A$2:$A$18,MATCH(D494,Part_Categories!$B$2:$B$18,0))&"-01","CHECK") -> CAR-06E-SAF-01 | F494: =E494&".jpg" -> CAR-06E-SAF-01.jpg | G494: =IFERROR(INDEX(Series!$F$2:$F$30,MATCH(C494,Series!$B$2:$B$30,0)),"") -> 06E (sizes to add) | K494: To Shoot | O494: =C494&" "&D494&" spare part - Efforts Engineers" -> Carrier 06E Series Safety Head and Relief Valve spare part - Efforts Engineers | P494: =IFERROR("/"&LOWER(B494)&"/"&INDEX(Series!$D$2:$D$30,MATCH(C494,Series!$B$2:$B$30,0))&"/"&INDEX(Part_Categories!$C$2:$C$18,MATCH(D494,Part_Categories!$B$2:$B$18,0)),"CHECK") -> /carrier/06e/safety-head-and-relief-valve

Sheet Series
A1: Brand | B1: Series | C1: Series Code | D1: URL Slug | E1: Type / Drive | F1: Models Covered (summary text) | G1: Models Listed | H1: Photo Slots | I1: Uploaded | J1: % Uploaded
A2: Grasso | B2: Grasso V Series | C2: V | D2: v-series | E2: Reciprocating, single and two-stage, belt or direct drive | F2: V 300, V 450, V 600, V 700, V 1100, V 1400 | G2: =COUNTIFS(Model_List!$B$2:$B$171,B2) -> 6 | H2: =COUNTIFS(Master_Photo_Sheet!$C$2:$C$494,B2) -> 17 | I2: =COUNTIFS(Master_Photo_Sheet!$C$2:$C$494,B2,Master_Photo_Sheet!$K$2:$K$494,"Uploaded") -> 0 | J2: =IF(H2-COUNTIFS(Master_Photo_Sheet!$C$2:$C$494,B2,Master_Photo_Sheet!$K$2:$K$494,"Not Applicable")=0,0,I2/(H2-COUNTIFS(Master_Photo_Sheet!$C$2:$C$494,B2,Master_Photo_Sheet!$K$2:$K$494,"Not Applicable"))) -> 0
A3: Grasso | B3: Grasso V HP and V XHP Series | C3: VHP | D3: v-hp-xhp | E3: Reciprocating, high-pressure / heat-pump duty | F3: V 350 XHP, V 550 XHP, V 750 XHP, V 950 XHP, V HP (sizes to add) | G3: =COUNTIFS(Model_List!$B$2:$B$171,B3) -> 5 | H3: =COUNTIFS(Master_Photo_Sheet!$C$2:$C$494,B3) -> 17 | I3: =COUNTIFS(Master_Photo_Sheet!$C$2:$C$494,B3,Master_Photo_Sheet!$K$2:$K$494,"Uploaded") -> 0 | J3: =IF(H3-COUNTIFS(Master_Photo_Sheet!$C$2:$C$494,B3,Master_Photo_Sheet!$K$2:$K$494,"Not Applicable")=0,0,I3/(H3-COUNTIFS(Master_Photo_Sheet!$C$2:$C$494,B3,Master_Photo_Sheet!$K$2:$K$494,"Not Applicable"))) -> 0
A4: Grasso | B4: Grasso 5HP Series | C4: 5HP | D4: 5hp | E4: Reciprocating, single-stage, direct drive (CO2 / NH3 heat pump) | F4: 35 HP, 45 HP, 55 HP, 65 HP | G4: =COUNTIFS(Model_List!$B$2:$B$171,B4) -> 4 | H4: =COUNTIFS(Master_Photo_Sheet!$C$2:$C$494,B4) -> 17 | I4: =COUNTIFS(Master_Photo_Sheet!$C$2:$C$494,B4,Master_Photo_Sheet!$K$2:$K$494,"Uploaded") -> 0 | J4: =IF(H4-COUNTIFS(Master_Photo_Sheet!$C$2:$C$494,B4,Master_Photo_Sheet!$K$2:$K$494,"Not Applicable")=0,0,I4/(H4-COUNTIFS(Master_Photo_Sheet!$C$2:$C$494,B4,Master_Photo_Sheet!$K$2:$K$494,"Not Applicable"))) -> 0
A5: Grasso | B5: Grasso RC 11 Series | C5: RC11 | D5: rc-11 | E5: Reciprocating, older RC range | F5: RC 211, RC 311, RC 611, RC 6311 | G5: =COUNTIFS(Model_List!$B$2:$B$171,B5) -> 4 | H5: =COUNTIFS(Master_Photo_Sheet!$C$2:$C$494,B5) -> 17 | I5: =COUNTIFS(Master_Photo_Sheet!$C$2:$C$494,B5,Master_Photo_Sheet!$K$2:$K$494,"Uploaded") -> 0 | J5: =IF(H5-COUNTIFS(Master_Photo_Sheet!$C$2:$C$494,B5,Master_Photo_Sheet!$K$2:$K$494,"Not Applicable")=0,0,I5/(H5-COUNTIFS(Master_Photo_Sheet!$C$2:$C$494,B5,Master_Photo_Sheet!$K$2:$K$494,"Not Applicable"))) -> 0
A6: Grasso | B6: Grasso RC 12 Series | C6: RC12 | D6: rc-12 | E6: Reciprocating, older RC range | F6: RC 212, RC 312, RC 412, RC 512, RC 612, RC 912, RC 1212, RC 2112, RC 3112, RC 4212, RC 5112, RC 6312, RC 7212, RC 8412, RC 9312, RC 10212 | G6: =COUNTIFS(Model_List!$B$2:$B$171,B6) -> 16 | H6: =COUNTIFS(Master_Photo_Sheet!$C$2:$C$494,B6) -> 17 | I6: =COUNTIFS(Master_Photo_Sheet!$C$2:$C$494,B6,Master_Photo_Sheet!$K$2:$K$494,"Uploaded") -> 0 | J6: =IF(H6-COUNTIFS(Master_Photo_Sheet!$C$2:$C$494,B6,Master_Photo_Sheet!$K$2:$K$494,"Not Applicable")=0,0,I6/(H6-COUNTIFS(Master_Photo_Sheet!$C$2:$C$494,B6,Master_Photo_Sheet!$K$2:$K$494,"Not Applicable"))) -> 0
A7: Sabroe | B7: Sabroe CMO Series | C7: CMO | D7: cmo | E7: Reciprocating, single and two-stage | F7: CMO 14, CMO 16, CMO 18, CMO 24, CMO 26, CMO 28, TCMO 28 | G7: =COUNTIFS(Model_List!$B$2:$B$171,B7) -> 7 | H7: =COUNTIFS(Master_Photo_Sheet!$C$2:$C$494,B7) -> 17 | I7: =COUNTIFS(Master_Photo_Sheet!$C$2:$C$494,B7,Master_Photo_Sheet!$K$2:$K$494,"Uploaded") -> 0 | J7: =IF(H7-COUNTIFS(Master_Photo_Sheet!$C$2:$C$494,B7,Master_Photo_Sheet!$K$2:$K$494,"Not Applicable")=0,0,I7/(H7-COUNTIFS(Master_Photo_Sheet!$C$2:$C$494,B7,Master_Photo_Sheet!$K$2:$K$494,"Not Applicable"))) -> 0
A8: Sabroe | B8: Sabroe SMC 65 Series | C8: SMC65 | D8: smc-65 | E8: Reciprocating, single and two-stage | F8: SMC 2-65, SMC 3-65, SMC 4-65, SMC 6-65, SMC 8-65, SMC 10-65, TSMC 8-65 | G8: =COUNTIFS(Model_List!$B$2:$B$171,B8) -> 7 | H8: =COUNTIFS(Master_Photo_Sheet!$C$2:$C$494,B8) -> 17 | I8: =COUNTIFS(Master_Photo_Sheet!$C$2:$C$494,B8,Master_Photo_Sheet!$K$2:$K$494,"Uploaded") -> 0 | J8: =IF(H8-COUNTIFS(Master_Photo_Sheet!$C$2:$C$494,B8,Master_Photo_Sheet!$K$2:$K$494,"Not Applicable")=0,0,I8/(H8-COUNTIFS(Master_Photo_Sheet!$C$2:$C$494,B8,Master_Photo_Sheet!$K$2:$K$494,"Not Applicable"))) -> 0
A9: Sabroe | B9: Sabroe SMC 100 Series | C9: SMC100 | D9: smc-100 | E9: Reciprocating, single and two-stage | F9: SMC 104S, SMC 104L, SMC 104E, SMC 106S, SMC 106L, SMC 106E, SMC 108S, SMC 108L, SMC 108E, SMC 112S, SMC 112L, SMC 112E, SMC 116S, SMC 116L, SMC 116E, SMC 4-100, SMC 6-100, SMC 8-100, TSMC 108S, TSMC 108L, TSMC 116S, TSMC 116L | G9: =COUNTIFS(Model_List!$B$2:$B$171,B9) -> 22 | H9: =COUNTIFS(Master_Photo_Sheet!$C$2:$C$494,B9) -> 17 | I9: =COUNTIFS(Master_Photo_Sheet!$C$2:$C$494,B9,Master_Photo_Sheet!$K$2:$K$494,"Uploaded") -> 0 | J9: =IF(H9-COUNTIFS(Master_Photo_Sheet!$C$2:$C$494,B9,Master_Photo_Sheet!$K$2:$K$494,"Not Applicable")=0,0,I9/(H9-COUNTIFS(Master_Photo_Sheet!$C$2:$C$494,B9,Master_Photo_Sheet!$K$2:$K$494,"Not Applicable"))) -> 0
A10: Sabroe | B10: Sabroe SMC 180 Series | C10: SMC180 | D10: smc-180 | E10: Reciprocating | F10: SMC 180 | G10: =COUNTIFS(Model_List!$B$2:$B$171,B10) -> 1 | H10: =COUNTIFS(Master_Photo_Sheet!$C$2:$C$494,B10) -> 17 | I10: =COUNTIFS(Master_Photo_Sheet!$C$2:$C$494,B10,Master_Photo_Sheet!$K$2:$K$494,"Uploaded") -> 0 | J10: =IF(H10-COUNTIFS(Master_Photo_Sheet!$C$2:$C$494,B10,Master_Photo_Sheet!$K$2:$K$494,"Not Applicable")=0,0,I10/(H10-COUNTIFS(Master_Photo_Sheet!$C$2:$C$494,B10,Master_Photo_Sheet!$K$2:$K$494,"Not Applicable"))) -> 0
A11: Sabroe | B11: Sabroe HPO and HPC Series | C11: HPO | D11: hpo-hpc | E11: Reciprocating, high-pressure (CO2 / NH3) | F11: HPO 24, HPO / HPC (other sizes to add) | G11: =COUNTIFS(Model_List!$B$2:$B$171,B11) -> 2 | H11: =COUNTIFS(Master_Photo_Sheet!$C$2:$C$494,B11) -> 17 | I11: =COUNTIFS(Master_Photo_Sheet!$C$2:$C$494,B11,Master_Photo_Sheet!$K$2:$K$494,"Uploaded") -> 0 | J11: =IF(H11-COUNTIFS(Master_Photo_Sheet!$C$2:$C$494,B11,Master_Photo_Sheet!$K$2:$K$494,"Not Applicable")=0,0,I11/(H11-COUNTIFS(Master_Photo_Sheet!$C$2:$C$494,B11,Master_Photo_Sheet!$K$2:$K$494,"Not Applicable"))) -> 0
A12: Kirloskar | B12: Kirloskar KC Series | C12: KC | D12: kc | E12: Reciprocating, single-stage | F12: KC 2, KC 3, KC 4, KC 6, KC 9, KC 12, KC 5 | G12: =COUNTIFS(Model_List!$B$2:$B$171,B12) -> 7 | H12: =COUNTIFS(Master_Photo_Sheet!$C$2:$C$494,B12) -> 17 | I12: =COUNTIFS(Master_Photo_Sheet!$C$2:$C$494,B12,Master_Photo_Sheet!$K$2:$K$494,"Uploaded") -> 0 | J12: =IF(H12-COUNTIFS(Master_Photo_Sheet!$C$2:$C$494,B12,Master_Photo_Sheet!$K$2:$K$494,"Not Applicable")=0,0,I12/(H12-COUNTIFS(Master_Photo_Sheet!$C$2:$C$494,B12,Master_Photo_Sheet!$K$2:$K$494,"Not Applicable"))) -> 0
A13: Kirloskar | B13: Kirloskar KC Two-Stage Series | C13: KC2S | D13: kc-two-stage | E13: Reciprocating, two-stage (low + high stage cylinders) | F13: KC 21, KC 31, KC 42, KC 51, KC 63, KC 72, KC 84, KC 93, KC 102 | G13: =COUNTIFS(Model_List!$B$2:$B$171,B13) -> 9 | H13: =COUNTIFS(Master_Photo_Sheet!$C$2:$C$494,B13) -> 17 | I13: =COUNTIFS(Master_Photo_Sheet!$C$2:$C$494,B13,Master_Photo_Sheet!$K$2:$K$494,"Uploaded") -> 0 | J13: =IF(H13-COUNTIFS(Master_Photo_Sheet!$C$2:$C$494,B13,Master_Photo_Sheet!$K$2:$K$494,"Not Applicable")=0,0,I13/(H13-COUNTIFS(Master_Photo_Sheet!$C$2:$C$494,B13,Master_Photo_Sheet!$K$2:$K$494,"Not Applicable"))) -> 0
... A30: Carrier | B30: Carrier 06E Series | C30: 06E | D30: 06e | E30: Carlyle / Voltas reciprocating | F30: 06E (sizes to add) | G30: =COUNTIFS(Model_List!$B$2:$B$171,B30) -> 1 | H30: =COUNTIFS(Master_Photo_Sheet!$C$2:$C$494,B30) -> 17 | I30: =COUNTIFS(Master_Photo_Sheet!$C$2:$C$494,B30,Master_Photo_Sheet!$K$2:$K$494,"Uploaded") -> 0 | J30: =IF(H30-COUNTIFS(Master_Photo_Sheet!$C$2:$C$494,B30,Master_Photo_Sheet!$K$2:$K$494,"Not Applicable")=0,0,I30/(H30-COUNTIFS(Master_Photo_Sheet!$C$2:$C$494,B30,Master_Photo_Sheet!$K$2:$K$494,"Not Applicable"))) -> 0

Sheet Model_List
A1: Brand | B1: Series | C1: Model | D1: Cylinders | E1: Data Confidence | F1: Source / Note
A2: Grasso | B2: Grasso V Series | C2: V 300 | D2: 4 | E2: Confirmed (OEM page) | F2: GEA Grasso V product page
A3: Grasso | B3: Grasso V Series | C3: V 450 | D3: 6 | E3: Confirmed (OEM page) | F3: GEA Grasso V product page
A4: Grasso | B4: Grasso V Series | C4: V 600 | D4: 8 | E4: Confirmed (OEM page) | F4: GEA Grasso V product page
A5: Grasso | B5: Grasso V Series | C5: V 700 | D5: 4 | E5: Confirmed (OEM page) | F5: GEA Grasso V product page
A6: Grasso | B6: Grasso V Series | C6: V 1100 | D6: 6 | E6: Confirmed (OEM page) | F6: GEA Grasso V product page
A7: Grasso | B7: Grasso V Series | C7: V 1400 | E7: Confirmed (OEM page) | F7: GEA single-stage table; cylinder count to add
A8: Grasso | B8: Grasso V HP and V XHP Series | C8: V 350 XHP | E8: Confirmed (OEM page) | F8: GEA V XHP page
A9: Grasso | B9: Grasso V HP and V XHP Series | C9: V 550 XHP | E9: Confirmed (OEM page) | F9: GEA V XHP page
A10: Grasso | B10: Grasso V HP and V XHP Series | C10: V 750 XHP | E10: Confirmed (OEM page) | F10: GEA V XHP page
A11: Grasso | B11: Grasso V HP and V XHP Series | C11: V 950 XHP | E11: Confirmed (OEM page) | F11: GEA V XHP page
A12: Grasso | B12: Grasso V HP and V XHP Series | C12: V HP (sizes to add) | E12: Verify with team | F12: GEA lists V HP / V HS lines; add exact sizes
A13: Grasso | B13: Grasso 5HP Series | C13: 35 HP | D13: 3 | E13: Verify with team | F13: Four sizes of 3 to 6 cylinders per GEA; 35 HP size name inferred
A14: Grasso | B14: Grasso 5HP Series | C14: 45 HP | D14: 4 | E14: Confirmed (OEM page) | F14: GEA 5HP page
A15: Grasso | B15: Grasso 5HP Series | C15: 55 HP | D15: 5 | E15: Confirmed (OEM page) | F15: GEA 5HP page
A16: Grasso | B16: Grasso 5HP Series | C16: 65 HP | D16: 6 | E16: Confirmed (OEM page) | F16: GEA 5HP page
A17: Grasso | B17: Grasso RC 11 Series | C17: RC 211 | D17: 2 | E17: Seen in supplier / used listings | F17: Used-equipment listing
A18: Grasso | B18: Grasso RC 11 Series | C18: RC 311 | E18: Seen in supplier / used listings | F18: Used-equipment listing
A19: Grasso | B19: Grasso RC 11 Series | C19: RC 611 | D19: 6 | E19: Seen in supplier / used listings | F19: Used-equipment listing
A20: Grasso | B20: Grasso RC 11 Series | C20: RC 6311 | E20: Seen in supplier / used listings | F20: Used-equipment listing
A21: Grasso | B21: Grasso RC 12 Series | C21: RC 212 | E21: Seen in supplier / used listings | F21: Supplier model list (verify against Grasso manual)
A22: Grasso | B22: Grasso RC 12 Series | C22: RC 312 | E22: Seen in supplier / used listings | F22: Supplier model list (verify against Grasso manual)
A23: Grasso | B23: Grasso RC 12 Series | C23: RC 412 | E23: Seen in supplier / used listings | F23: Supplier model list (verify against Grasso manual)
A24: Grasso | B24: Grasso RC 12 Series | C24: RC 512 | E24: Seen in supplier / used listings | F24: Supplier model list (verify against Grasso manual)
A25: Grasso | B25: Grasso RC 12 Series | C25: RC 612 | E25: Seen in supplier / used listings | F25: Supplier model list (verify against Grasso manual)
A26: Grasso | B26: Grasso RC 12 Series | C26: RC 912 | E26: Seen in supplier / used listings | F26: Supplier model list (verify against Grasso manual)
A27: Grasso | B27: Grasso RC 12 Series | C27: RC 1212 | E27: Seen in supplier / used listings | F27: Supplier model list (verify against Grasso manual)
A28: Grasso | B28: Grasso RC 12 Series | C28: RC 2112 | E28: Seen in supplier / used listings | F28: Supplier model list (verify against Grasso manual)
A29: Grasso | B29: Grasso RC 12 Series | C29: RC 3112 | E29: Seen in supplier / used listings | F29: Supplier model list (verify against Grasso manual)
A30: Grasso | B30: Grasso RC 12 Series | C30: RC 4212 | E30: Seen in supplier / used listings | F30: Supplier model list (verify against Grasso manual)
A31: Grasso | B31: Grasso RC 12 Series | C31: RC 5112 | E31: Seen in supplier / used listings | F31: Supplier model list (verify against Grasso manual)
... A43: Sabroe | B43: Sabroe CMO Series | C43: TCMO 28 | E43: Seen in supplier / used listings | F43: Supplier model list / manual title
A44: Sabroe | B44: Sabroe SMC 65 Series | C44: SMC 2-65 | D44: 2 | E44: Seen in supplier / used listings | F44: Supplier model list
A45: Sabroe | B45: Sabroe SMC 65 Series | C45: SMC 3-65 | D45: 3 | E45: Seen in supplier / used listings | F45: Supplier model list
A46: Sabroe | B46: Sabroe SMC 65 Series | C46: SMC 4-65 | D46: 4 | E46: Seen in supplier / used listings | F46: Supplier model list
A47: Sabroe | B47: Sabroe SMC 65 Series | C47: SMC 6-65 | D47: 6 | E47: Seen in supplier / used listings | F47: Supplier model list
A48: Sabroe | B48: Sabroe SMC 65 Series | C48: SMC 8-65 | D48: 8 | E48: Seen in supplier / used listings | F48: Supplier model list
A49: Sabroe | B49: Sabroe SMC 65 Series | C49: SMC 10-65 | D49: 10 | E49: Seen in supplier / used listings | F49: Supplier model list
A50: Sabroe | B50: Sabroe SMC 65 Series | C50: TSMC 8-65 | D50: 8 | E50: Seen in supplier / used listings | F50: Supplier model list; two-stage
A51: Sabroe | B51: Sabroe SMC 100 Series | C51: SMC 104S | D51: 4 | E51: Seen in supplier / used listings | F51: Supplier model list / used listings
...

Sheet Part_Categories
A1: Part Code | B1: Part Category | C1: URL Slug | D1: Photo Tip
A2: CLN | B2: Cylinder Liner | C2: cylinder-liner | D2: Top view showing the bore plus a side view; place a ruler or caliper in frame
A3: PST | B3: Piston Assembly | C3: piston-assembly | D3: Side view with rings fitted, plus one shot of the crown
A4: PRG | B4: Piston Ring Set | C4: piston-ring-set | D4: Full set in a row, compression rings and oil scraper rings labelled
A5: CRD | B5: Connecting Rod | C5: connecting-rod | D5: Flat lay with big end and small end both visible
A6: CRK | B6: Crankshaft | C6: crankshaft | D6: Full length on foam supports, plus a close-up of the journals
A7: PIN | B7: Gudgeon Pin and Bush | C7: gudgeon-pin-and-bush | D7: Pin and bush side by side
A8: BRG | B8: Main Bearing and Bush | C8: main-bearing-and-bush | D8: Show both halves of the bearing, bore side up
A9: SVP | B9: Suction Valve Plate | C9: suction-valve-plate | D9: Plate face-up, then a second shot of the seating side
A10: DVA | B10: Discharge Valve Assembly | C10: discharge-valve-assembly | D10: Assembled valve from the top, and one angled shot
A11: VSP | B11: Valve Spring and Cage | C11: valve-spring-and-cage | D11: Springs and cage laid out together
A12: HDC | B12: Cylinder Head Cover | C12: cylinder-head-cover | D12: Angled shot showing ports and mounting face
... A18: SAF | B18: Safety Head and Relief Valve | C18: safety-head-and-relief-valve | D18: Front view plus one angled view

Sheet Lists
A1: Brand | B1: Brand Code | D1: Photo Status | F1: Photo Source | H1: Photo View | J1: Stock Status
A2: Grasso | B2: GRA | D2: To Shoot | F2: Own photo | H2: Front | J2: In Stock
A3: Sabroe | B3: SAB | D3: Shot | F3: Supplier photo | H3: Angled | J3: On Order
A4: Kirloskar | B4: KIR | D4: Edited | F4: Customer photo | H4: Top | J4: Enquire
A5: Vilter | B5: VIL | D5: Uploaded | H5: Set / Kit
A6: Mycom | B6: MYC | D6: Not Applicable | H6: With ruler
A7: Carrier | B7: CAR
